Workbook

Sheet Summary
A1: S3W2 - Regression suite and production content audit
A2: Grand Prix ticket explorer - Team 27, Capstone 2026. Sources: Sprint 2 user stories and acceptance criteria, S3W1 accessibility and error-handling criteria, Sprint 2 defects G-01 to G-16, and the Production Content Standard (CS-01 to CS-16). Run on the deployed site on 18 Oct 2026 in the Claude desktop app's built-in browser, signed in, at about 800px and 375px widths. Re-checked on the new front end the same evening.
A4: Regression by area | B4: Pass | C4: Fail | D4: Blocked | E4: Not built | F4: Not tested | G4: Total
A5: Entry and navigation | B5: =COUNTIFS('Regression Scenarios'!$B:$B,$A5,'Regression Scenarios'!$J:$J,"Pass") -> 4 | C5: =COUNTIFS('Regression Scenarios'!$B:$B,$A5,'Regression Scenarios'!$J:$J,"Fail") -> 0 | D5: =COUNTIFS('Regression Scenarios'!$B:$B,$A5,'Regression Scenarios'!$J:$J,"Blocked") -> 0 | E5: =COUNTIFS('Regression Scenarios'!$B:$B,$A5,'Regression Scenarios'!$J:$J,"Not built") -> 0 | F5: =COUNTIFS('Regression Scenarios'!$B:$B,$A5,'Regression Scenarios'!$J:$J,"Not tested") -> 0 | G5: =SUM(B5:F5) -> 4
A6: Browse | B6: =COUNTIFS('Regression Scenarios'!$B:$B,$A6,'Regression Scenarios'!$J:$J,"Pass") -> 4 | C6: =COUNTIFS('Regression Scenarios'!$B:$B,$A6,'Regression Scenarios'!$J:$J,"Fail") -> 1 | D6: =COUNTIFS('Regression Scenarios'!$B:$B,$A6,'Regression Scenarios'!$J:$J,"Blocked") -> 0 | E6: =COUNTIFS('Regression Scenarios'!$B:$B,$A6,'Regression Scenarios'!$J:$J,"Not built") -> 3 | F6: =COUNTIFS('Regression Scenarios'!$B:$B,$A6,'Regression Scenarios'!$J:$J,"Not tested") -> 0 | G6: =SUM(B6:F6) -> 8
A7: Detail | B7: =COUNTIFS('Regression Scenarios'!$B:$B,$A7,'Regression Scenarios'!$J:$J,"Pass") -> 3 | C7: =COUNTIFS('Regression Scenarios'!$B:$B,$A7,'Regression Scenarios'!$J:$J,"Fail") -> 2 | D7: =COUNTIFS('Regression Scenarios'!$B:$B,$A7,'Regression Scenarios'!$J:$J,"Blocked") -> 1 | E7: =COUNTIFS('Regression Scenarios'!$B:$B,$A7,'Regression Scenarios'!$J:$J,"Not built") -> 2 | F7: =COUNTIFS('Regression Scenarios'!$B:$B,$A7,'Regression Scenarios'!$J:$J,"Not tested") -> 0 | G7: =SUM(B7:F7) -> 8
A8: Selection limits | B8: =COUNTIFS('Regression Scenarios'!$B:$B,$A8,'Regression Scenarios'!$J:$J,"Pass") -> 7 | C8: =COUNTIFS('Regression Scenarios'!$B:$B,$A8,'Regression Scenarios'!$J:$J,"Fail") -> 0 | D8: =COUNTIFS('Regression Scenarios'!$B:$B,$A8,'Regression Scenarios'!$J:$J,"Blocked") -> 0 | E8: =COUNTIFS('Regression Scenarios'!$B:$B,$A8,'Regression Scenarios'!$J:$J,"Not built") -> 1 | F8: =COUNTIFS('Regression Scenarios'!$B:$B,$A8,'Regression Scenarios'!$J:$J,"Not tested") -> 0 | G8: =SUM(B8:F8) -> 8
A9: Compare | B9: =COUNTIFS('Regression Scenarios'!$B:$B,$A9,'Regression Scenarios'!$J:$J,"Pass") -> 4 | C9: =COUNTIFS('Regression Scenarios'!$B:$B,$A9,'Regression Scenarios'!$J:$J,"Fail") -> 1 | D9: =COUNTIFS('Regression Scenarios'!$B:$B,$A9,'Regression Scenarios'!$J:$J,"Blocked") -> 0 | E9: =COUNTIFS('Regression Scenarios'!$B:$B,$A9,'Regression Scenarios'!$J:$J,"Not built") -> 1 | F9: =COUNTIFS('Regression Scenarios'!$B:$B,$A9,'Regression Scenarios'!$J:$J,"Not tested") -> 0 | G9: =SUM(B9:F9) -> 6
A10: Fallback states | B10: =COUNTIFS('Regression Scenarios'!$B:$B,$A10,'Regression Scenarios'!$J:$J,"Pass") -> 1 | C10: =COUNTIFS('Regression Scenarios'!$B:$B,$A10,'Regression Scenarios'!$J:$J,"Fail") -> 0 | D10: =COUNTIFS('Regression Scenarios'!$B:$B,$A10,'Regression Scenarios'!$J:$J,"Blocked") -> 6 | E10: =COUNTIFS('Regression Scenarios'!$B:$B,$A10,'Regression Scenarios'!$J:$J,"Not built") -> 0 | F10: =COUNTIFS('Regression Scenarios'!$B:$B,$A10,'Regression Scenarios'!$J:$J,"Not tested") -> 0 | G10: =SUM(B10:F10) -> 7
A11: Firestore read failures | B11: =COUNTIFS('Regression Scenarios'!$B:$B,$A11,'Regression Scenarios'!$J:$J,"Pass") -> 2 | C11: =COUNTIFS('Regression Scenarios'!$B:$B,$A11,'Regression Scenarios'!$J:$J,"Fail") -> 2 | D11: =COUNTIFS('Regression Scenarios'!$B:$B,$A11,'Regression Scenarios'!$J:$J,"Blocked") -> 2 | E11: =COUNTIFS('Regression Scenarios'!$B:$B,$A11,'Regression Scenarios'!$J:$J,"Not built") -> 2 | F11: =COUNTIFS('Regression Scenarios'!$B:$B,$A11,'Regression Scenarios'!$J:$J,"Not tested") -> 0 | G11: =SUM(B11:F11) -> 8
A12: Accessibility smoke | B12: =COUNTIFS('Regression Scenarios'!$B:$B,$A12,'Regression Scenarios'!$J:$J,"Pass") -> 4 | C12: =COUNTIFS('Regression Scenarios'!$B:$B,$A12,'Regression Scenarios'!$J:$J,"Fail") -> 0 | D12: =COUNTIFS('Regression Scenarios'!$B:$B,$A12,'Regression Scenarios'!$J:$J,"Blocked") -> 0 | E12: =COUNTIFS('Regression Scenarios'!$B:$B,$A12,'Regression Scenarios'!$J:$J,"Not built") -> 0 | F12: =COUNTIFS('Regression Scenarios'!$B:$B,$A12,'Regression Scenarios'!$J:$J,"Not tested") -> 0 | G12: =SUM(B12:F12) -> 4
A13: Total | B13: =SUM(B5:B12) -> 29 | C13: =SUM(C5:C12) -> 6 | D13: =SUM(D5:D12) -> 9 | E13: =SUM(E5:E12) -> 9 | F13: =SUM(F5:F12) -> 0 | G13: =SUM(G5:G12) -> 53
A14: Pass rate (of scenarios run) | G14: =IF(G13-F13=0,0,B13/(G13-F13)) -> 0.54716981
A16: Content audit and links | B16: Pass | C16: Fail | D16: N/A | E16: Not tested | G16: Total
A17: Content audit checks | B17: =COUNTIF('Content Audit'!$G:$G,"Pass") -> 28 | C17: =COUNTIF('Content Audit'!$G:$G,"Fail") -> 23 | D17: =COUNTIF('Content Audit'!$G:$G,"N/A") -> 0 | E17: =COUNTIF('Content Audit'!$G:$G,"Not tested") -> 4 | G17: =SUM(B17:E17) -> 55
A18: Links (Yes = resolves) | B18: =COUNTIF('Link Check'!$F:$F,"Yes") -> 13 | C18: =COUNTIF('Link Check'!$F:$F,"No") -> 3 | D18: =COUNTIF('Link Check'!$F:$F,"N/A") -> 6 | G18: =SUM(B18:D18) -> 22
A20: Gaps by severity | B20: Critical | C20: High | D20: Medium | E20: Low | F20: Open | G20: Total
A21: Gap List | B21: =COUNTIF('Gap List'!$H$3:$H$52,"Critical") -> 0 | C21: =COUNTIF('Gap List'!$H$3:$H$52,"High") -> 4 | D21: =COUNTIF('Gap List'!$H$3:$H$52,"Medium") -> 10 | E21: =COUNTIF('Gap List'!$H$3:$H$52,"Low") -> 13 | F21: =COUNTIF('Gap List'!$K$3:$K$52,"Open")+COUNTIF('Gap List'!$K$3:$K$52,"In progress") -> 19 | G21: =SUM(B21:E21) -> 27
A23: How to use
A24: Yellow cells are for you to fill in. Run everything on the deployed site, at desktop (1440px) and mobile (375px) widths.
A25: 1. Regression Scenarios (53): run each one, write the Actual result and pick a Result. P1 scenarios first; they are the smoke test for every release.
A26: 2. Content Audit (55 checks): check each screen against the Production Content Standard rule shown. N/A if the screen doesn't have that content.
A27: 3. Link Check: click every link and navigating button, record where it goes and whether it resolves. Replace [bracketed] rows with the real links.
A28: 4. Gap List: log every Fail and every link that doesn't resolve, with a severity, then put the Gap ID back on the row that found it.
A29: 5. Hand the Gap List to both developers with severities (last checklist item).
A30: Selection limit and Compare scenarios assume Compare takes 2-3 tickets (S3W1 Q-02, still to confirm). Adjust Then if the team decides otherwise.
A31: Severity: Critical = blocks the journey or shows wrong info; High = breaks a rule users notice; Medium = inconsistent but usable; Low = cosmetic.

Sheet Regression Scenarios
A1: ID | B1: Area | C1: Priority | D1: Source (AC / S3W1 / defect / CS) | E1: Scenario | F1: Given | G1: When | H1: Then (expected) | I1: Actual result | J1: Result | K1: Gap ID | L1: Date tested | M1: Notes
A2: ENTRY AND NAVIGATION
A3: RS-01 | B3: Entry and navigation | C3: P1 | D3: S1 AC | E3: Reach the ticket explorer | F3: User is signed in on the Dashboard | G3: User selects "Browse tickets" | H3: Browse page opens and lists ticket types; URL is /tickets | I3: Dashboard "Browse tickets" opens /tickets with all 6 ticket types | J3: Pass | L3: 18/10/2026
A4: RS-02 | B4: Entry and navigation | C4: P1 | D4: S1 AC | E4: Direct link to Browse | F4: User is signed in | G4: User opens /tickets directly or refreshes it | H4: Browse loads the same as from the Dashboard | I4: Opening /tickets directly loads Browse; signed-out users are sent to sign-in and back | J4: Pass | L4: 18/10/2026
A5: RS-03 | B5: Entry and navigation | C5: P2 | D5: CS-14 | E5: Page titles | F5: User moves between Dashboard, Browse and Compare | G5: User checks the browser tab title | H5: Each page has its own title, e.g. "Tickets - [site name]" | I5: App pages titled "Dashboard | Grand Prix Ticketing", "Browse tickets | ...", "Compare tickets | ..." | J5: Pass | L5: 18/10/2026 | M5: Public home page title is just "Home" (S3-02)
A6: RS-04 | B6: Entry and navigation | C6: P2 | D6: S2 Q-10 | E6: Browser back from Browse | F6: User came from the Dashboard to Browse | G6: User presses the browser back button | H6: User returns to the Dashboard with no error | I6: Browser back from Browse returns to the Dashboard | J6: Pass | L6: 18/10/2026
A7: BROWSE
A8: RS-05 | B8: Browse | C8: P1 | D8: S1 AC | E8: All ticket types on one screen | F8: Ticket data loads | G8: User opens Browse | H8: Every ticket type shows as a card; none are missing or duplicated | I8: 6 ticket types shown as cards, no duplicates | J8: Pass | L8: 18/10/2026
A9: RS-06 | B9: Browse | C9: P1 | D9: S1 AC / CS-01 / CS-02 | E9: Card content | F9: Ticket data loads | G9: User reads any card | H9: Card shows tier name, price, zone, view quality and days covered, formatted per CS-01 and CS-02 | I9: Name, price, zone and days shown; no tier badge or view quality indicator; days shown as day names | J9: Fail | K9: S3-04 | L9: 18/10/2026 | M9: Also S3-03 (dates). Sprint 2 G-01 and G-09 still open
A10: RS-07 | B10: Browse | C10: P1 | D10: S1 AC / G-02 | E10: Ticket order | F10: Several ticket types with different prices | G10: User opens Browse | H10: Cards follow the agreed recommended order, with price ascending as tie-breaker | I10: Sorted by price ascending: $235, $545, $620, $890, $1,150, $4,950 | J10: Pass | L10: 18/10/2026 | M10: Sprint 2 G-02 fixed
A11: RS-08 | B11: Browse | C11: P2 | D11: S1 AC / CS-07 | E11: Sold-out card | F11: One ticket type has 0 left | G11: User views that card | H11: "Sold out" label shows, button is disabled, card is muted but readable | I11: No stock data; sold-out state can't occur | J11: Not built | K11: S3-07 | L11: 18/10/2026 | M11: G-04 still open
A12: RS-09 | B12: Browse | C12: P2 | D12: S1 AC / CS-07 | E12: Low-stock label | F12: One ticket type has fewer than 20 left | G12: User views that card | H12: "Only X left" shows with the right number; button stays enabled | I12: No stock data; low-stock label can't occur | J12: Not built | K12: S3-07 | L12: 18/10/2026
A13: RS-10 | B13: Browse | C13: P2 | D13: S1 AC / G-05 | E13: Price range | F13: One ticket type has more than one price | G13: User views that card | H13: Card shows a range, e.g. "$450-$550" | I13: One price per ticket type; ranges not supported | J13: Not built | K13: S3-08 | L13: 18/10/2026 | M13: G-05 still open
A14: RS-11 | B14: Browse | C14: P2 | D14: S1 Responsive | E14: Mobile layout | F14: Screen is 375px wide | G14: User opens Browse | H14: Cards stack in one column; no text cut off; no sideways scrolling | I14: At 375px cards stack in one column; no sideways scroll; no text under 12px; all buttons at least 44px | J14: Pass | L14: 18/10/2026 | M14: Sprint 2 G-08 (button size) fixed
A15: RS-12 | B15: Browse | C15: P3 | D15: S1 Interactions / G-03 | E15: Hover and pressed states | F15: Desktop browser | G15: User hovers a card, then clicks and holds a button | H15: Card shows a hover state; button shows a pressed state | I15: Pressing and holding a button doesn't change its look (no pressed/active state) | J15: Pass | L15: 18/10/2026 | M15: Tested by Matthew in Chrome, new front end. Sprint 2 G-03 (active state) still open. Accepted as a pass by the BA: difference is marginal
A16: DETAIL
A17: RS-13 | B17: Detail | C17: P1 | D17: S2 AC | E17: Open the right ticket | F17: Browse is loaded | G17: User selects "View details" on the Grandstand card | H17: Detail opens for Grandstand with the same price, days and zone as its card | I17: "View details" on Turn 11 opens a modal with matching name, price, days and zone; URL updates to ?ticket=... | J17: Pass | L17: 18/10/2026
A18: RS-14 | B18: Detail | C18: P1 | D18: S2 AC / G-09 / CS-03 | E18: Real dates | F18: Detail is open for a multi-day ticket | G18: User reads the dates | H18: Actual dates show, e.g. "Fri 13 - Sun 15 Mar 2026", not just day names | I18: Shows "Sat, Sun" / "Thu, Fri, Sat, Sun", not real dates | J18: Fail | K18: S3-03 | L18: 18/10/2026 | M18: G-09 still open
A19: RS-15 | B19: Detail | C19: P1 | D19: S2 AC / G-10 / CS-04 | E19: Zone, seat description and map | F19: Detail is open | G19: User reads the zone section | H19: Zone name, a seat description and the zone map (with alt text) all show | I19: New front end: zone, map and description shown; every ticket still says "Seat allocation not specified for this ticket." | J19: Fail | K19: S3-05 | L19: 18/10/2026
A20: RS-16 | B20: Detail | C20: P2 | D20: S2 AC / CS-06 | E20: Includes and excludes | F20: Detail is open | G20: User reads both lists | H20: Both lists show, written per CS-06; empty Excludes reads "Not specified for this ticket" | I20: "What's included" and "What's not included" lists shown, parallel noun-first items | J20: Pass | L20: 18/10/2026
A21: RS-17 | B21: Detail | C21: P2 | D21: S2 Edge / G-13 / CS-16 | E21: Restriction callout | F21: Ticket has a restriction such as 18+ | G21: User opens Detail | H21: Restriction shows in a visible callout | I21: No ticket in the catalogue has a restriction to check | J21: Blocked | L21: 18/10/2026 | M21: Needs a test ticket with a restriction (G-13)
A22: RS-18 | B22: Detail | C22: P1 | D22: S2 Interactions / G-11 | E22: Add to cart | F22: Cart is empty | G22: User selects "Add to cart" | H22: Cart count goes from 0 to 1 and a confirmation appears | I22: No Add to cart; button is "Add to selection"; /cart and /checkout return 404 | J22: Not built | K22: S3-06 | L22: 18/10/2026 | M22: G-11 still open
A23: RS-19 | B23: Detail | C23: P2 | D23: S2 Q-07 | E23: Add the same ticket twice | F23: Ticket is already in the cart | G23: User selects "Add to cart" again | H23: Quantity goes up by 1; no duplicate line | I23: No cart, so can't add twice | J23: Not built | K23: S3-06 | L23: 18/10/2026
A24: RS-20 | B24: Detail | C24: P2 | D24: S2 Interactions | E24: Close keeps position | F24: User scrolled down Browse, then opened Detail | G24: User closes Detail with X or Esc | H24: Browse shows at the same scroll position; focus returns to the "View details" button | I24: Esc closes the modal and focus returns to the "View details" button; focus stays inside the modal while open | J24: Pass | L24: 18/10/2026
A25: SELECTION LIMITS
A26: RS-21 | B26: Selection limits | C26: P1 | D26: Compare (Q-02) | E26: Select tickets to compare | F26: Browse is loaded | G26: User selects 2 tickets for comparison | H26: Both show as selected and a "Compare tickets" action becomes available | I26: New front end: ticking "Compare" on 2 cards shows "2 ticket types selected" and a Compare link | J26: Pass | L26: 18/10/2026 | M26: Selection is now a Compare checkbox on each card
A27: RS-22 | B27: Selection limits | C27: P1 | D27: Compare (Q-02) | E27: Maximum selection | F27: 3 tickets are already selected | G27: User tries to select a 4th | H27: The 4th isn't added and a message says "You can compare up to 3 tickets" | I27: At 3, the other Compare checkboxes are disabled; text says "Remove one to select another." | J27: Pass | L27: 18/10/2026
A28: RS-23 | B28: Selection limits | C28: P1 | D28: Compare (Q-02) / EMP-05 | E28: Minimum selection | F28: Only 1 ticket is selected | G28: User tries to compare | H28: Compare isn't available, or shows "Add at least one more ticket to compare" | I28: With 1 selected there is no Compare link; Compare page says "You need to select at least two ticket types before comparing." | J28: Pass | L28: 18/10/2026
A29: RS-24 | B29: Selection limits | C29: P2 | D29: Compare (Q-02) | E29: Deselect a ticket | F29: 2 tickets are selected | G29: User deselects one | H29: Selection count drops to 1 and the compare action updates | I29: Remove drops the count and updates the compare link | J29: Pass | L29: 18/10/2026
A30: RS-25 | B30: Selection limits | C30: P2 | D30: Compare (Q-02) | E30: Same ticket twice | F30: A ticket is already selected | G30: User selects it again | H30: It isn't added twice; selecting again removes it or does nothing | I30: Selecting the same ticket again removes it (toggle) | J30: Pass | L30: 18/10/2026
A31: RS-26 | B31: Selection limits | C31: P2 | D31: Compare (Q-02) | E31: Sold-out tickets | F31: One ticket type is sold out | G31: User tries to select it for comparison | H31: Behaviour matches the agreed rule (can compare but not buy, or can't select) and is clearly labelled | I31: No stock data, so no sold-out tickets to try | J31: Not built | K31: S3-07 | L31: 18/10/2026
A32: RS-27 | B32: Selection limits | C32: P2 | D32: Compare (Q-02) | E32: Selection survives navigation | F32: 2 tickets are selected | G32: User opens Detail for another ticket, then closes it | H32: The 2 tickets are still selected | I32: Selection kept when going Browse -> Compare, but lost on page refresh | J32: Pass | K32: S3-13 | L32: 18/10/2026 | M32: Refresh loss logged as Low
A33: RS-28 | B33: Selection limits | C33: P3 | D33: Compare (Q-02) | E33: Clear all | F33: 3 tickets are selected | G33: User selects "Clear all" | H33: All selections are removed | I33: "Clear selection" resets to 0 selected | J33: Pass | L33: 18/10/2026
A34: COMPARE
A35: RS-29 | B35: Compare | C35: P1 | D35: Compare (Q-02) | E35: Side-by-side comparison | F35: 2 or 3 tickets are selected | G35: User opens Compare | H35: Selected tickets show side by side with the same rows for each | I35: 3 tickets shown side by side in a table: map, price, days, zone, view, includes, excludes; differing rows highlighted | J35: Pass | L35: 18/10/2026
A36: RS-30 | B36: Compare | C36: P1 | D36: Compare / CS-01 to CS-03 | E36: Values match other screens | F36: Compare is open | G36: User checks price, dates and zone against Browse and Detail | H36: All values match exactly | I36: Prices, days and zones match Browse and Detail exactly | J36: Pass | L36: 18/10/2026
A37: RS-31 | B37: Compare | C37: P2 | D37: Compare | E37: Remove from Compare | F37: 3 tickets are compared | G37: User removes one | H37: It disappears and the other 2 stay; focus moves sensibly | I37: New front end: Remove works, but focus still drops to the page body | J37: Fail | K37: S3-14 | L37: 18/10/2026
A38: RS-32 | B38: Compare | C38: P2 | D38: EMP-04 | E38: Compare with nothing selected | F38: No tickets are selected | G38: User opens Compare | H38: "Select 2 or 3 tickets to compare" shows with a "Browse tickets" link | I38: Shows "Select at least two tickets to compare..." with a "Browse tickets" link | J38: Pass | L38: 18/10/2026 | M38: Wording differs slightly from EMP-04 but meets the intent
A39: RS-33 | B39: Compare | C39: P2 | D39: Compare / S1 Responsive | E39: Compare on mobile | F39: Screen is 375px wide | G39: User opens Compare with 3 tickets | H39: Content stacks or scrolls within its own area; no page-wide sideways scrolling | I39: At phone width with 3 tickets, Compare shows but the page has a little sideways play when scrolled left | J39: Pass | L39: 18/10/2026 | M39: Tested by Matthew in Chrome device mode. Swiping right triggers the browser's back gesture, which is expected. Accepted as a pass by the BA: difference is marginal
A40: RS-34 | B40: Compare | C40: P2 | D40: Compare | E40: Add to cart from Compare | F40: Compare is open | G40: User adds one ticket to the cart | H40: That ticket is added, the cart count updates, and Compare stays open | I40: No Add to cart on Compare | J40: Not built | K40: S3-06 | L40: 18/10/2026
...

Sheet Content Audit
A1: ID | B1: Screen | C1: Rule | D1: Rule name | E1: Passes when | F1: What I saw | G1: Result | H1: Gap ID | I1: Notes
A2: DASHBOARD
A3: CA-01 | B3: Dashboard | C3: CS-08 | D3: Button labels | E3: Verb first, sentence case, same label for same action | F3: Mobile bottom nav calls the Dashboard "Home"; sidebar calls it "Dashboard" | G3: Fail | H3: S3-23
A4: CA-02 | B4: Dashboard | C4: CS-10 | D4: Spelling, grammar and case | E4: Australian English, no typos, sentence case | F4: No spelling issues found | G4: Pass
A5: CA-03 | B5: Dashboard | C5: CS-11 | D5: No placeholder or test content | E5: No lorem ipsum, TBD, test, undefined, null, NaN | F5: Ticket pass shows "Your Name", "QR", "Row 1 · Seat 1" | G5: Fail | H5: S3-10
A6: CA-04 | B6: Dashboard | C6: CS-12 | D6: Brand | E6: Grand Prix palette (red, black, white) and typography | F6: Colours now Grand Prix red and black (S3-17 closed), but the logo says "GARAGE", the template name | G6: Fail | H6: S3-21
A7: CA-05 | B7: Dashboard | C7: CS-13 | D7: Images | E7: No broken images; meaningful images have alt text | G7: Not tested
A8: CA-06 | B8: Dashboard | C8: CS-14 | D8: Page titles and headings | E8: Unique page title; one main heading | F8: "Dashboard | Grand Prix Ticketing" | G8: Pass
A9: CA-07 | B9: Dashboard | C9: CS-15 | D9: Links | E9: Descriptive text; resolves; goes where it says (see Link Check) | F9: 10 links go to "#" and do nothing | G9: Fail | H9: S3-09
A10: BROWSE
A11: CA-08 | B11: Browse | C11: CS-01 | D11: Ticket names | E11: Official tier name, Title Case, 40 chars or fewer, same on every screen | F11: Same 6 names on Browse, Detail and Compare | G11: Pass
A12: CA-09 | B12: Browse | C12: CS-02 | D12: Prices | E12: $ sign, whole dollars, ranges with a dash; never $0 or NaN | F12: "$235 AUD" ... "$4,950 AUD" | G12: Pass
A13: CA-10 | B13: Browse | C13: CS-03 | D13: Dates | E13: Real dates with day names, e.g. Fri 13 - Sun 15 Mar 2026 | F13: Day names only: "Thu, Fri, Sat, Sun" | G13: Fail | H13: S3-03
A14: CA-11 | B14: Browse | C14: CS-07 | D14: Stock labels | E14: Exactly "Sold out" / "Only X left", shown as text | F14: No stock labels exist | G14: Fail | H14: S3-07
A15: CA-12 | B15: Browse | C15: CS-08 | D15: Button labels | E15: Verb first, sentence case, same label for same action | F15: "View details", "Add to selection", "Highlight zone", "Clear selection" | G15: Pass
A16: CA-13 | B16: Browse | C16: CS-09 | D16: Error, empty and fallback messages | E16: Match S3W1 ERR/EMP/FS wording; no technical text | G16: Not tested
A17: CA-14 | B17: Browse | C17: CS-10 | D17: Spelling, grammar and case | E17: Australian English, no typos, sentence case | F17: Ticket names, buttons and headings shown in ALL CAPS | G17: Fail | H17: S3-24
A18: CA-15 | B18: Browse | C18: CS-11 | D18: No placeholder or test content | E18: No lorem ipsum, TBD, test, undefined, null, NaN | F18: Tickets page now also shows the "Your Name" / "Row 1 · Seat 1" pass | G18: Fail | H18: S3-10
A19: CA-16 | B19: Browse | C19: CS-12 | D19: Brand | E19: Grand Prix palette (red, black, white) and typography | F19: Colours now Grand Prix red and black (S3-17 closed), but the logo says "GARAGE", the template name | G19: Fail | H19: S3-21
A20: CA-17 | B20: Browse | C20: CS-13 | D20: Images | E20: No broken images; meaningful images have alt text | F20: Each card map is labelled with its zone | G20: Pass
A21: CA-18 | B21: Browse | C21: CS-14 | D21: Page titles and headings | E21: Unique page title; one main heading | F21: "Browse tickets | Grand Prix Ticketing", one h1 | G21: Pass
A22: CA-19 | B22: Browse | C22: CS-15 | D22: Links | E22: Descriptive text; resolves; goes where it says (see Link Check) | F22: Tickets page now also has 8 links to "#" (upgrades and events) | G22: Fail | H22: S3-09
A23: DETAIL
A24: CA-20 | B24: Detail | C24: CS-01 | D24: Ticket names | E24: Official tier name, Title Case, 40 chars or fewer, same on every screen | F24: Matches card | G24: Pass
A25: CA-21 | B25: Detail | C25: CS-02 | D25: Prices | E25: $ sign, whole dollars, ranges with a dash; never $0 or NaN | F25: Matches card | G25: Pass
A26: CA-22 | B26: Detail | C26: CS-03 | D26: Dates | E26: Real dates with day names, e.g. Fri 13 - Sun 15 Mar 2026 | F26: Day names only | G26: Fail | H26: S3-03
A27: CA-23 | B27: Detail | C27: CS-04 | D27: Zone and seat | E27: Zone name plus a 1-2 sentence seat description | F27: "Seat allocation not specified for this ticket." on every ticket | G27: Fail | H27: S3-05
A28: CA-24 | B28: Detail | C28: CS-05 | D28: View description | E28: Plain language, 15-60 words; else "View description coming soon" | F28: Plain one-sentence view descriptions | G28: Pass
A29: CA-25 | B29: Detail | C29: CS-06 | D29: Includes and excludes | E29: Parallel noun-first items, sentence case, no full stops | F29: Parallel noun-first items, no full stops | G29: Pass
A30: CA-26 | B30: Detail | C30: CS-07 | D30: Stock labels | E30: Exactly "Sold out" / "Only X left", shown as text | F30: No stock labels exist | G30: Fail | H30: S3-07
A31: CA-27 | B31: Detail | C31: CS-08 | D31: Button labels | E31: Verb first, sentence case, same label for same action | F31: "Add to selection" (no Add to cart) | G31: Fail | H31: S3-06
A32: CA-28 | B32: Detail | C32: CS-09 | D32: Error, empty and fallback messages | E32: Match S3W1 ERR/EMP/FS wording; no technical text | F32: "Ticket not found" message is plain with a next step | G32: Pass
A33: CA-29 | B33: Detail | C33: CS-10 | D33: Spelling, grammar and case | E33: Australian English, no typos, sentence case | F33: Ticket names, buttons and headings shown in ALL CAPS | G33: Fail | H33: S3-24
A34: CA-30 | B34: Detail | C34: CS-11 | D34: No placeholder or test content | E34: No lorem ipsum, TBD, test, undefined, null, NaN | F34: No placeholder text | G34: Pass
A35: CA-31 | B35: Detail | C35: CS-12 | D35: Brand | E35: Grand Prix palette (red, black, white) and typography | F35: Colours now Grand Prix red and black (S3-17 closed), but the logo says "GARAGE", the template name | G35: Fail | H35: S3-21
A36: CA-32 | B36: Detail | C36: CS-13 | D36: Images | E36: No broken images; meaningful images have alt text | F36: Map alt "Albert Park Grand Prix Circuit map" | G36: Pass
A37: CA-33 | B37: Detail | C37: CS-15 | D37: Links | E37: Descriptive text; resolves; goes where it says (see Link Check) | F37: "Back to browse" resolves | G37: Pass
A38: CA-34 | B38: Detail | C38: CS-16 | D38: Restrictions and conditions | E38: Age limits etc. in a visible callout | F38: No ticket has a restriction to check | G38: Not tested
A39: COMPARE
A40: CA-35 | B40: Compare | C40: CS-01 | D40: Ticket names | E40: Official tier name, Title Case, 40 chars or fewer, same on every screen | F40: Matches Browse | G40: Pass
...

Sheet Link Check
A1: ID | B1: Screen | C1: Link or button text | D1: Expected destination | E1: Actual destination | F1: Resolves? | G1: Gap ID | H1: Notes
A2: LC-01 | B2: Dashboard | C2: Browse tickets | D2: /tickets (Browse) | E2: /tickets | F2: Yes
A3: LC-02 | B3: Dashboard | C3: [each other Dashboard link] | D3: [its page] | E3: Full standings, View full calendar, View all upgrades, 3 Upgrade links, 4 event links all go to "#" | F3: No | G3: S3-09 | H3: 10 dead links
A4: LC-03 | B4: Header / nav | C4: [each header link, e.g. logo, Home] | D4: [its page] | E4: Dashboard, Tickets, Team, Profile, Settings all load; Sign out button present | F4: Yes
A5: LC-04 | B5: Browse | C5: View details (each of the 6 ticket types) | D5: Detail for that ticket | E5: Opens the right ticket in a modal (?ticket=...) | F5: Yes | H5: All 6 checked
A6: LC-05 | B6: Browse | C6: Compare tickets | D6: Compare with the selected tickets | E6: /tickets/compare with the selected tickets | F6: Yes
A7: LC-06 | B7: Browse | C7: Join the waitlist (sold-out empty state) | D7: Waitlist / availability notification page | E7: No sold-out state, so no waitlist link | F7: N/A | H7: Depends on G-04
A8: LC-07 | B8: Browse | C8: Clear filters (no-results state) | D8: Full ticket list | E8: No filters on Browse | F8: N/A
A9: LC-08 | B9: Browse | C9: Retry (error state) | D9: Reloads tickets on the same page | H9: Not tested: needs offline mode
A10: LC-09 | B10: Detail | C10: Close (X) | D10: Back to Browse, same scroll position | E10: Closes modal, back to Browse | F10: Yes
A11: LC-10 | B11: Detail | C11: Add to cart | D11: Adds to cart; cart count updates | E11: No Add to cart; /cart returns 404 | F11: No | G11: S3-06
A12: LC-11 | B12: Detail | C12: Back to tickets (ticket not found) | D12: /tickets (Browse) | E12: "Back to browse" returns to /tickets | F12: Yes | H12: Label is "Back to browse"
A13: LC-12 | B13: Detail | C13: [any other link in the modal] | D13: [its page] | E13: No other links in the modal | F13: N/A
A14: LC-13 | B14: Compare | C14: Browse tickets (nothing selected) | D14: /tickets (Browse) | E14: /tickets | F14: Yes
A15: LC-14 | B15: Compare | C15: Remove (each ticket) | D15: Removes that ticket, stays on Compare | E15: Removes the ticket, stays on Compare | F15: Yes
A16: LC-15 | B16: Compare | C16: View details (each ticket) | D16: Detail for that ticket | E16: No View details on Compare | F16: N/A
A17: LC-16 | B17: Compare | C17: Add to cart (each ticket) | D17: Adds to cart; cart count updates | E17: No Add to cart on Compare | F17: No | G17: S3-06
A18: LC-17 | B18: Footer | C18: [each footer link, e.g. Terms, Privacy, FAQ, Contact] | D18: [its page] | E18: No footer on app pages | F18: N/A
A19: LC-18 | B19: Cart | C19: Cart icon / link | D19: Cart or checkout page | E19: No cart icon | F19: N/A
A20: LC-19 | B20: Home | C20: Sign in | D20: /auth/signin | E20: /auth/signin | F20: Yes
A21: LC-20 | B21: Home | C21: Get your tickets | D21: /auth/signup | E21: /auth/signup | F21: Yes
A22: LC-21 | B22: Browse | C22: Back to dashboard | D22: /dashboard | E22: /dashboard | F22: Yes
A23: LC-22 | B23: Compare | C23: Back to tickets | D23: /tickets | E23: /tickets | F23: Yes
A24: LC-23 | B24: Header | C24: Profile icon | D24: /profile | E24: /profile | F24: Yes
A25: LC-24
A26: LC-25
A27: LC-26
A28: LC-27
A29: LC-28
A31: Rows in [brackets] are placeholders: add one row per real link you find on that screen.

Sheet Gap List
A1: Gap ID | B1: Title | C1: Found in (RS / CA / LC ID) | D1: Screen | E1: Steps to reproduce | F1: Expected | G1: Actual | H1: Severity | I1: Screenshot link | J1: Assigned to | K1: Status | L1: Date logged
A2: S3-00 (example) | B2: Waitlist link returns 404 | C2: LC-06, CA-15 | D2: Browse | E2: 1. Make every ticket type sold out 2. Open /tickets 3. Select "Join the waitlist" | F2: Waitlist page opens | G2: 404 page | H2: High | I2: (paste link) | J2: (developer) | K2: Open | L2: 17/10/2026
A3: S3-01 | B3: Leftover template text in meta description | C3: CA (Error and empty states, CS-11) | D3: Sign in / Sign up | E3: 1. Open /auth/signin 2. View page source or a link preview | F3: A real description of the site | G3: "Built on garage-boilerplate" | H3: Low | K3: Open | L3: 18/10/2026
A4: S3-02 | B4: Home page title is just "Home" | C4: RS-03 | D4: Home | E4: 1. Open the home page 2. Read the browser tab | F4: "Home | Grand Prix Ticketing" | G4: "Home" | H4: Low | K4: Open | L4: 18/10/2026
A5: S3-03 | B5: Day names shown instead of real dates | C5: RS-06, RS-14, CA CS-03 | D5: Browse, Detail, Compare | E5: 1. Open /tickets 2. Read "Days covered" on any 4-day ticket | F5: Real dates: day, date and month | G5: "Thu, Fri, Sat, Sun" (Sprint 2 G-09 still open) | H5: Medium | K5: Open | L5: 18/10/2026
A6: S3-04 | B6: No tier badge or view quality indicator on cards | C6: RS-06 | D6: Browse | E6: 1. Open /tickets 2. Look at any card | F6: Tier badge/label and a view quality indicator | G6: Neither shown (Sprint 2 G-01 still open) | H6: Medium | K6: Open | L6: 18/10/2026
A7: S3-05 | B7: No seat description on any ticket | C7: RS-15, CA CS-04 | D7: Detail, Compare | E7: 1. Open details for any ticket 2. Read "Zone and location" | F7: 1-2 sentence seat description | G7: "Seat allocation not specified for this ticket." on all 6 | H7: Medium | K7: Open | L7: 18/10/2026
A8: S3-06 | B8: No cart: no Add to cart, /cart is 404 | C8: RS-18, RS-19, RS-34, LC-10, LC-16 | D8: Detail, Compare | E8: 1. Open any ticket's details 2. Look for Add to cart 3. Open /cart | F8: Add to cart updates a cart count | G8: Only "Add to selection"; /cart and /checkout return 404 (Sprint 2 G-11 still open) | H8: High | K8: Open | L8: 18/10/2026
A9: S3-07 | B9: Stock and availability not built | C9: RS-08, RS-09, RS-26, RS-36, CA CS-07 | D9: Browse, Detail, Compare | E9: 1. Open /tickets 2. Look for sold-out or low-stock labels | F9: "Sold out" and "Only X left" states | G9: No stock data, so these states never appear (Sprint 2 G-04 still open) | H9: High | K9: Open | L9: 18/10/2026
A10: S3-08 | B10: Price ranges not supported | C10: RS-10 | D10: Browse | E10: 1. Check any ticket type | F10: Range shown where a type has several prices | G10: One price per type (Sprint 2 G-05 still open) | H10: Medium | K10: Open | L10: 18/10/2026
A11: S3-09 | B11: 18 links go nowhere (Dashboard and Tickets pages) | C11: LC-02, CA CS-15 | D11: Dashboard | E11: 1. Open /dashboard 2. Click Full standings, View full calendar, View all upgrades, any Upgrade or any event | F11: Each opens its page | G11: All link to "#" and nothing happens. New front end: the same upgrade and event links also appear on /tickets (8 more) | H11: High | K11: Open | L11: 18/10/2026
A12: S3-10 | B12: Placeholder content on Dashboard ticket pass | C12: CA CS-11 | D12: Dashboard, Tickets | E12: 1. Open /dashboard 2. Look at "Your tickets" | F12: The user's real name, QR code and seat | G12: "Your Name", "QR", "Row 1 · Seat 1" | H12: Medium | K12: Open | L12: 18/10/2026
A13: S3-11 | B13: Race dates inconsistent across pages | C13: CA CS-03 | D13: Dashboard | E13: 1. Open /dashboard and read the race dates 2. Compare with the home page and ticket days | F13: Same race week dates everywhere | G13: Dashboard says "1 – 2 January"; home says 4-day race week; tickets cover Thu-Sun | H13: Medium | K13: Open | L13: 18/10/2026
A14: S3-12 | B14: Placeholder Settings page | C14: CA CS-11 | D14: Settings | E14: 1. Open /settings | F14: Real settings, or remove the link | G14: "Settings will appear here." | H14: Low | K14: Open | L14: 18/10/2026
... A16: S3-14 | B16: Focus lost after removing a ticket on Compare | C16: RS-31 | D16: Compare | E16: 1. Compare 3 tickets 2. Press Remove on one using the keyboard | F16: Focus moves to the next ticket or heading | G16: Focus drops to the page body | H16: Low | K16: Open | L16: 18/10/2026
A17: S3-15 | B17: Subtitle text contrast below 4.5:1 | C17: RS-52 | D17: Browse | E17: 1. Open /tickets 2. Check "Explore Australian Grand Prix ticket types..." in WebAIM | F17: At least 4.5:1 | G17: About 4.0:1 (grey on near-black) | H17: Medium | I17: Closed 18/10 on new front end: subtitle text now passes contrast | K17: Closed | L17: 18/10/2026
A18: S3-16 | B18: Limit-reached buttons' names don't match their text | C18: RS-53 | D18: Browse | E18: 1. Select 3 tickets 2. Inspect a "Selection limit reached" button | F18: Accessible name includes "Selection limit reached" | G18: Name is only the ticket name (WCAG 2.5.3) | H18: Low | I18: Closed 18/10 on new front end: Compare checkboxes have matching labels | K18: Closed | L18: 18/10/2026
A19: S3-17 | B19: Colours don't match Grand Prix brand | C19: CA CS-12 | D19: All | E19: 1. Open any page 2. Compare with the Grand Prix style guide | F19: Grand Prix red, black and white | G19: Green accents (Sprint 2 G-15 still open) | H19: Medium | I19: Closed 18/10 on new front end: red and black palette | K19: Closed | L19: 18/10/2026
A20: S3-18 | B20: Spinner instead of skeleton cards while loading | C20: RS-35 | D20: Browse | E20: 1. Open /tickets in Chrome 2. DevTools > Network > Slow 3G 3. Reload (Cmd+Shift+R) | F20: Skeleton placeholder per card, replaced by real cards | G20: A single spinner until all tickets load (Sprint 2 G-07 still open) | H20: Medium | I20: See Screenshots tab; Closed 18/10 on new front end: skeleton cards show while loading | K20: Closed | L20: 18/10/2026
A21: S3-19 | B21: Circuit map shows a blank box while loading | C21: RS-35 | D21: Browse, Detail, Compare | E21: 1. Same as S3-18 2. Watch the map area on each card as it appears | F21: A sized placeholder (or skeleton) that clearly shows the map is loading | G21: Blank white/grey box until the track image loads | H21: Low | I21: See Screenshots tab; Closed 18/10 on new front end: skeleton covers the map area while loading | K21: Closed | L21: 18/10/2026
A22: S3-20 | B22: Header shows "Welcome back, User" before the real name loads | C22: RS-35 | D22: All signed-in pages | E22: 1. Throttle to 3G 2. Reload /tickets 3. Watch the header | F22: Name appears once loaded, or no name until then | G22: "Welcome back, User" shows first, then changes to the account name | H22: Low | I22: Closed 18/10 on new front end: no "Welcome back, User" header | K22: Closed | L22: 18/10/2026
A23: S3-21 | B23: Logo says "GARAGE" (template name) | C23: CA CS-12 | D23: All signed-in pages | E23: 1. Sign in 2. Look at the sidebar or top-left logo | F23: Grand Prix Ticketing name and logo | G23: "GARAGE", from the garage-boilerplate template | H23: Medium | K23: Open | L23: 18/10/2026
A24: S3-22 | B24: Compare checkbox is small | C24: RS-21 (Detail) | D24: Detail | E24: 1. Open any ticket's details 2. Measure the Compare checkbox | F24: At least 44px tap target (team standard, see S3W1 Q-03) | G24: 24px checkbox | H24: Low | K24: Open | L24: 18/10/2026
A25: S3-23 | B25: Dashboard has two different names | C25: CA CS-08 | D25: Navigation | E25: 1. Compare the sidebar with the mobile bottom nav | F25: Same label in both | G25: Sidebar "Dashboard", bottom nav "Home" | H25: Low | K25: Open | L25: 18/10/2026
A26: S3-24 | B26: Ticket names and buttons in all caps | C26: CA CS-10 | D26: Browse, Detail, Compare | E26: 1. Open /tickets | F26: Sentence or title case (CS-01, CS-10) | G26: ALL CAPS ticket names, buttons and headings; harder to read | H26: Low | K26: Open | L26: 18/10/2026
A27: S3-25 | B27: Ticket load failure shows an endless spinner | C27: RS-43 to RS-46 | D27: Browse | E27: 1. Open /tickets in Chrome 2. DevTools > Network: right-click documents:runQuery > Block request domain 3. Reload (Cmd+Shift+R) | F27: "We couldn't load tickets right now. Please try again." with a Retry button, shown within 10 seconds (S3W1 ERR-01 to ERR-03, FS-02) | G27: Loading spinner forever; no message, no Retry, no timeout. Users can't tell anything is wrong | H27: High | I27: See Screenshots tab | K27: Open | L27: 18/10/2026
A28: S3-26 | B28: No pressed state on buttons | C28: RS-12 | D28: All | E28: 1. Open /tickets on desktop 2. Click and hold "View details" | F28: Button visibly changes while pressed | G28: No change while held (Sprint 2 G-03 still open) | H28: Low | I28: Accepted as marginal by the BA, 18/10/2026 | K28: Won't fix | L28: 18/10/2026
A29: S3-27 | B29: Compare page shifts sideways on mobile | C29: RS-33 | D29: Compare | E29: 1. Chrome device mode, 375px 2. Select 3 tickets, open Compare 3. Scroll left | F29: Only the comparison area scrolls sideways; the page stays put | G29: The whole page moves slightly sideways | H29: Low | I29: Accepted as marginal by the BA, 18/10/2026 | K29: Won't fix | L29: 18/10/2026
A30: S3-28
A31: S3-29
A32: S3-30
A33: S3-31
A34: S3-32
A35: S3-33
A36: S3-34
A37: S3-35
A38: S3-36
A39: S3-37
A40: S3-38
A41: S3-39
...

Sheet Screenshots
A1: Evidence screenshots
A3: S3-18 / S3-20: on 3G, /tickets shows only a spinner, and the header says "Welcome back, User" (18/10/2026)
A36: S3-19: cards appear with blank white boxes where the circuit map should be, while albert-park-circuit.png is still loading (18/10/2026)
A70: New front end on 3G (18/10/2026): skeleton cards (S3-18 closed), red palette (S3-17 closed), "GARAGE" logo (S3-21), "Your Name" / "Row 1 · Seat 1" placeholders (S3-10)
A105: S3-25: firestore.googleapis.com blocked in DevTools; /tickets shows an endless spinner with no message or Retry (18/10/2026)
